Workbook
Name Tabella01AprileInverter: Tabella01MarzoInverter[]

Sheet PR_Calc
A1: PR CALCULATION
A2: 05 MAGGIO 2026 | BS2: 5 May 2026 PR Calculation
A3: Total VALUES | BN3: =COUNT(TabellaMar2026[[#All],[Colonna1]]) -> 96 | BS3: Total VALUES (4 values for each hour) | BW3: =+BN3 -> 96
A4: PVSyst PR for current month | BN4: 0.897 | BS4: Total values with POA>50 | BW4: =COUNTIF(H15:H110,">0") -> 48
A5: RAW PR | BN5: =((SUM(Tabella01MarzoInverter[[Active power TX1-INV-1]:[Active power TX1-INV-12]], Tabella01MarzoInverter[[Active power TX2-INV-1]:[Active power TX2-INV-12]], Tabella01MarzoInverter[[Active power TX3-INV-1]:[Active power TX3-INV-12]]) * 0.25) + SUM(AD$15:AD$110, AT$15:AT$110, BJ$15:BJ$110) ) / (12625 * (SUM($H$15:$H$110) * 0.25 / 1000)) -> 0.87094974 | BS5: PVSyst PR for current month | BW5: =+BN4*100 -> 89.7
A6: Irradiance Acceptance Rate [%] | BN6: 0.03 | BS6: RAW PR (calculated with each power and POA value) [%] | BW6: =+BN5*100 -> 87.094974
A7: Irradiance Minimum Value Accepted for calculation [%] | BN7: 50 | BS7: Average of each PR [%] | BW7: =AVERAGE(TabellaMar2026[[#Totals],[Colonna24]:[Colonna20]],TabellaMar2026[[#Totals],[Colonna39]:[Colonna6]],TabellaMar2026[[#Totals],[Colonna54]:[Colonna53]])*100 -> 87.142781
A8: NOMINAL VALUES | BS8: PR from SCADA [%] | BW8: 87.094974
A9: TX.INV | O9: 1.1 | P9: 1.2 | Q9: 1.3 | R9: 1.4 | S9: 1.5 | T9: 1.6 | U9: 1.7 | V9: 1.8 | W9: 1.9 | X9: 1.10 | Y9: 1.11 | Z9: 1.12 | AE9: 2.1 | AF9: 2.2 | AG9: 2.3 | AH9: 2.4 | AI9: 2.5 | AJ9: 2.6 | AK9: 2.7 | AL9: 2.8 | AM9: 2.9 | AN9: 2.10 | AO9: 2.11 | AP9: 2.12 | AU9: 3.1 | AV9: 3.2 | AW9: 3.3 | AX9: 3.4 | AY9: 3.5 | AZ9: 3.6 | BA9: 3.7 | BB9: 3.8 | BC9: 3.9 | BD9: 3.10 | BE9: 3.11 | BF9: 3.12 | BS9: Irradiance Acceptance Rate (for average between sensors)[%] | BW9: =+BN6*100 -> 3
A10: Potenza nominale DC | O10: 343.75 | P10: 343.75 | Q10: 343.75 | R10: 343.75 | S10: 343.75 | T10: 343.75 | U10: 343.75 | V10: 359.375 | W10: 359.375 | X10: 359.375 | Y10: 359.375 | Z10: 343.75 | AE10: 328.125 | AF10: 343.75 | AG10: 343.75 | AH10: 328.125 | AI10: 328.125 | AJ10: 359.375 | AK10: 343.75 | AL10: 359.375 | AM10: 359.375 | AN10: 343.75 | AO10: 359.375 | AP10: 359.375 | AU10: 359.375 | AV10: 359.375 | AW10: 359.375 | AX10: 359.375 | AY10: 359.375 | AZ10: 359.375 | BA10: 359.375 | BB10: 359.375 | BC10: 359.375 | BD10: 359.375 | BE10: 359.375 | BF10: 328.125 | BS10: Irradiance Minimum Value Accepted for calculation | BW10: =+BN7 -> 50
A11: Potenza nominale AC | O11: 320 | P11: 320 | Q11: 320 | R11: 320 | S11: 320 | T11: 320 | U11: 320 | V11: 320 | W11: 320 | X11: 320 | Y11: 320 | Z11: 320 | AE11: 320 | AF11: 320 | AG11: 320 | AH11: 320 | AI11: 320 | AJ11: 320 | AK11: 320 | AL11: 320 | AM11: 320 | AN11: 320 | AO11: 320 | AP11: 320 | AU11: 320 | AV11: 320 | AW11: 320 | AX11: 320 | AY11: 320 | AZ11: 320 | BA11: 320 | BB11: 320 | BC11: 320 | BD11: 320 | BE11: 320 | BF11: 320
A14: Dati | B14: ORA | C14: Irradiance TX1 [W/m2] A | D14: Irradiance TX1 [KWh/m2] A | E14: Irradiance TX3 [W/m2] B | F14: Irradiance TX3 [KWh/m2] B | G14: Irradiance Avg [KWh/m2] C = (A-B)/2 | H14: Irradiance Average>50 [W/m2] | I14: Irradiance Conditional MAX [KWh/m2] | J14: Difference [%] (B-A)/C | K14: Meter Reading (Previous day) D | L14: Meter Reading (Current day) E | M14: Energia attiva prod. (export meter) [kWh] F = (E - D)*1000 | N14: Potenza Attiva Limit Ratio | O14: Inverter status TX1-INV-1 | P14: Inverter status TX1-INV-2 | Q14: Inverter status TX1-INV-3 | R14: Inverter status TX1-INV-4 | S14: Inverter status TX1-INV-5 | T14: Inverter status TX1-INV-6 | U14: Inverter status TX1-INV-7 | V14: Inverter status TX1-INV-8 | W14: Inverter status TX1-INV-9 | X14: Inverter status TX1-INV-10 | Y14: Inverter status TX1-INV-11 | Z14: Inverter status TX1-INV-12 | AA14: Energy Loss for TX1 kW/H | AB14: Inverter status TX2-INV-1 | AC14: Inverter status TX2-INV-2 | AD14: TX1 Total loss | AE14: Inverter status TX2-INV-1 | AF14: Inverter status TX2-INV-2 | AG14: Inverter status TX2-INV-3 | AH14: Inverter status TX2-INV-4 | AI14: Inverter status TX2-INV-5 | AJ14: Inverter status TX2-INV-6 | AK14: Inverter status TX2-INV-7 | AL14: Inverter status TX2-INV-8 | AM14: Inverter status TX2-INV-9 | AN14: Inverter status TX2-INV-10 | AO14: Inverter status TX2-INV-11 | AP14: Inverter status TX2-INV-12 | AQ14: TX2 - Average Power | AR14: TX2 - Max Power | AS14: TX2 - Min Power | AT14: Enegy Loss for TX2 kW/H | AU14: Inverter status TX3-INV-1 | AV14: Inverter status TX3-INV-2 | AW14: Inverter status TX3-INV-3 | AX14: Inverter status TX3-INV-4 | AY14: Inverter status TX3-INV-5 | AZ14: Inverter status TX3-INV-6 | BA14: Inverter status TX3-INV-7 | BB14: Inverter status TX3-INV-8 | BC14: Inverter status TX3-INV-9 | BD14: Inverter status TX3-INV-10 | BE14: Inverter status TX3-INV-11 | BF14: Inverter status TX3-INV-12 | BG14: TX3 - Average Power | BH14: TX3 - Max Power | BI14: TX3 - Min Power | BJ14: Enegy Loss for TX3 kW/H | BK14: Normal PR calculation | BL14: Compensated PR | BM14: inverter sum test | BN14: Internal Availability [%] | BO14: External Availability [%] | BP14: PR after adjustments
A15: 46147 | B15: 00:00:00.000 | C15: -1 | D15: -0.00025 | E15: 0 | F15: 0 | G15: =IFERROR((D15+F15)/2, 0) -> -0.000125 | H15: =IFERROR(IF(AVERAGE(C15,E15)>$BN$7,AVERAGE(C15,E15),0), 0) -> 0 | I15: =IFERROR(IF(AND(D15=0,F15=0),0,IF(H15>$BN$6,MAX(D15,F15),G15)), 0) -> -0.000125 | J15: =IFERROR(IF(AND(D15>0,F15>0),ABS(D15-F15)/AVERAGE(D15,F15),0), 0) -> 0 | K15: 30386.2 | L15: 30386.2 | M15: =IFERROR((L15-K15)*1000, 0) -> 0 | N15: 0.876 | O15: {=IF( AND($H15 > $BN$7, Tabella01MarzoInverter[[#This Row],[Active power TX1-INV-1]] <= 0), IF( Tabella01MarzoInverter[[#This Row],[TX1 - Average Power]:[TX1 - Average Power]] > 0, Tabella01MarzoInverter[[#This Row],[TX1 - Average Power]:[TX1 - Average Power]] * 0.25, ($H15 / 1000) * O$10 * $BN$4 * 0.25 ), 0 ) + IF( $N15 < 0.875, MAX(0, MIN(($H15 / 1000) * O$10 * $BN$4, O$11 * 0.876) - (O$11 * $N15)) * 0.25, 0 )} -> 0 | P15: {=IF( AND($H15 > $BN$7, Tabella01MarzoInverter[[#This Row],[Active power TX1-INV-2]] <= 0), IF( Tabella01MarzoInverter[[#This Row],[TX1 - Average Power]:[TX1 - Average Power]] > 0, Tabella01MarzoInverter[[#This Row],[TX1 - Average Power]:[TX1 - Average Power]] * 0.25, ($H15 / 1000) * P$10 * $BN$4 * 0.25 ), 0 ) + IF( $N15 < 0.875, MAX(0, MIN(($H15 / 1000) * P$10 * $BN$4, P$11 * 0.876) - (P$11 * $N15)) * 0.25, 0 )} -> 0 | Q15: {=IF( AND($H15 > $BN$7, Tabella01MarzoInverter[[#This Row],[Active power TX1-INV-3]] <= 0), IF( Tabella01MarzoInverter[[#This Row],[TX1 - Average Power]:[TX1 - Average Power]] > 0, Tabella01MarzoInverter[[#This Row],[TX1 - Average Power]:[TX1 - Average Power]] * 0.25, ($H15 / 1000) * Q$10 * $BN$4 * 0.25 ), 0 ) + IF( $N15 < 0.875, MAX(0, MIN(($H15 / 1000) * Q$10 * $BN$4, Q$11 * 0.876) - (Q$11 * $N15)) * 0.25, 0 )} -> 0 | R15: {=IF( AND($H15 > $BN$7, Tabella01MarzoInverter[[#This Row],[Active power TX1-INV-4]] <= 0), IF( Tabella01MarzoInverter[[#This Row],[TX1 - Average Power]:[TX1 - Average Power]] > 0, Tabella01MarzoInverter[[#This Row],[TX1 - Average Power]:[TX1 - Average Power]] * 0.25, ($H15 / 1000) * R$10 * $BN$4 * 0.25 ), 0 ) + IF( $N15 < 0.875, MAX(0, MIN(($H15 / 1000) * R$10 * $BN$4, R$11 * 0.876) - (R$11 * $N15)) * 0.25, 0 )} -> 0 | S15: {=IF( AND($H15 > $BN$7, Tabella01MarzoInverter[[#This Row],[Active power TX1-INV-5]] <= 0), IF( Tabella01MarzoInverter[[#This Row],[TX1 - Average Power]:[TX1 - Average Power]] > 0, Tabella01MarzoInverter[[#This Row],[TX1 - Average Power]:[TX1 - Average Power]] * 0.25, ($H15 / 1000) * S$10 * $BN$4 * 0.25 ), 0 ) + IF( $N15 < 0.875, MAX(0, MIN(($H15 / 1000) * S$10 * $BN$4, S$11 * 0.876) - (S$11 * $N15)) * 0.25, 0 )} -> 0 | T15: {=IF( AND($H15 > $BN$7, Tabella01MarzoInverter[[#This Row],[Active power TX1-INV-6]] <= 0), IF( Tabella01MarzoInverter[[#This Row],[TX1 - Average Power]:[TX1 - Average Power]] > 0, Tabella01MarzoInverter[[#This Row],[TX1 - Average Power]:[TX1 - Average Power]] * 0.25, ($H15 / 1000) * T$10 * $BN$4 * 0.25 ), 0 ) + IF( $N15 < 0.875, MAX(0, MIN(($H15 / 1000) * T$10 * $BN$4, T$11 * 0.876) - (T$11 * $N15)) * 0.25, 0 )} -> 0 | U15: {=IF( AND($H15 > $BN$7, Tabella01MarzoInverter[[#This Row],[Active power TX1-INV-7]] <= 0), IF( Tabella01MarzoInverter[[#This Row],[TX1 - Average Power]:[TX1 - Average Power]] > 0, Tabella01MarzoInverter[[#This Row],[TX1 - Average Power]:[TX1 - Average Power]] * 0.25, ($H15 / 1000) * U$10 * $BN$4 * 0.25 ), 0 ) + IF( $N15 < 0.875, MAX(0, MIN(($H15 / 1000) * U$10 * $BN$4, U$11 * 0.876) - (U$11 * $N15)) * 0.25, 0 )} -> 0 | V15: {=IF( AND($H15 > $BN$7, Tabella01MarzoInverter[[#This Row],[Active power TX1-INV-8]] <= 0), IF( Tabella01MarzoInverter[[#This Row],[TX1 - Average Power]:[TX1 - Average Power]] > 0, Tabella01MarzoInverter[[#This Row],[TX1 - Average Power]:[TX1 - Average Power]] * 0.25, ($H15 / 1000) * V$10 * $BN$4 * 0.25 ), 0 ) + IF( $N15 < 0.875, MAX(0, MIN(($H15 / 1000) * V$10 * $BN$4, V$11 * 0.876) - (V$11 * $N15)) * 0.25, 0 )} -> 0 | W15: {=IF( AND($H15 > $BN$7, Tabella01MarzoInverter[[#This Row],[Active power TX1-INV-9]] <= 0), IF( Tabella01MarzoInverter[[#This Row],[TX1 - Average Power]:[TX1 - Average Power]] > 0, Tabella01MarzoInverter[[#This Row],[TX1 - Average Power]:[TX1 - Average Power]] * 0.25, ($H15 / 1000) * W$10 * $BN$4 * 0.25 ), 0 ) + IF( $N15 < 0.875, MAX(0, MIN(($H15 / 1000) * W$10 * $BN$4, W$11 * 0.876) - (W$11 * $N15)) * 0.25, 0 )} -> 0 | X15: {=IF( AND($H15 > $BN$7, Tabella01MarzoInverter[[#This Row],[Active power TX1-INV-10]] <= 0), IF( Tabella01MarzoInverter[[#This Row],[TX1 - Average Power]:[TX1 - Average Power]] > 0, Tabella01MarzoInverter[[#This Row],[TX1 - Average Power]:[TX1 - Average Power]] * 0.25, ($H15 / 1000) * X$10 * $BN$4 * 0.25 ), 0 ) + IF( $N15 < 0.875, MAX(0, MIN(($H15 / 1000) * X$10 * $BN$4, X$11 * 0.876) - (X$11 * $N15)) * 0.25, 0 )} -> 0 | Y15: {=IF( AND($H15 > $BN$7, Tabella01MarzoInverter[[#This Row],[Active power TX1-INV-11]] <= 0), IF( Tabella01MarzoInverter[[#This Row],[TX1 - Average Power]:[TX1 - Average Power]] > 0, Tabella01MarzoInverter[[#This Row],[TX1 - Average Power]:[TX1 - Average Power]] * 0.25, ($H15 / 1000) * Y$10 * $BN$4 * 0.25 ), 0 ) + IF( $N15 < 0.875, MAX(0, MIN(($H15 / 1000) * Y$10 * $BN$4, Y$11 * 0.876) - (Y$11 * $N15)) * 0.25, 0 )} -> 0 | Z15: {=IF( AND($H15 > $BN$7, Tabella01MarzoInverter[[#This Row],[Active power TX1-INV-12]] <= 0), IF( Tabella01MarzoInverter[[#This Row],[TX1 - Average Power]:[TX1 - Average Power]] > 0, Tabella01MarzoInverter[[#This Row],[TX1 - Average Power]:[TX1 - Average Power]] * 0.25, ($H15 / 1000) * Z$10 * $BN$4 * 0.25 ), 0 ) + IF( $N15 < 0.875, MAX(0, MIN(($H15 / 1000) * Z$10 * $BN$4, Z$11 * 0.876) - (Z$11 * $N15)) * 0.25, 0 )} -> 0 | AA15: {=IF( AND($H15 > $BN$7, Tabella01MarzoInverter[[#This Row],[TX1 - Average Power]] <= 0), IF( Tabella01MarzoInverter[[#This Row],[TX1 - Average Power]:[TX1 - Average Power]] > 0, Tabella01MarzoInverter[[#This Row],[TX1 - Average Power]:[TX1 - Average Power]] * 0.25, ($H15 / 1000) * AA$10 * $BN$4 * 0.25 ), 0 ) + IF( $N15 < 0.875, MAX(0, MIN(($H15 / 1000) * AA$10 * $BN$4, AA$11 * 0.876) - (AA$11 * $N15)) * 0.25, 0 )} -> 0 | AB15: {=IF( AND($H15 > $BN$7, Tabella01MarzoInverter[[#This Row],[TX1 - Max Power]] <= 0), IF( Tabella01MarzoInverter[[#This Row],[TX1 - Average Power]:[TX1 - Average Power]] > 0, Tabella01MarzoInverter[[#This Row],[TX1 - Average Power]:[TX1 - Average Power]] * 0.25, ($H15 / 1000) * AB$10 * $BN$4 * 0.25 ), 0 ) + IF( $N15 < 0.875, MAX(0, MIN(($H15 / 1000) * AB$10 * $BN$4, AB$11 * 0.876) - (AB$11 * $N15)) * 0.25, 0 )} -> 0 | AC15: {=IF( AND($H15 > $BN$7, Tabella01MarzoInverter[[#This Row],[TX1 - Min Power]] <= 0), IF( Tabella01MarzoInverter[[#This Row],[TX1 - Average Power]:[TX1 - Average Power]] > 0, Tabella01MarzoInverter[[#This Row],[TX1 - Average Power]:[TX1 - Average Power]] * 0.25, ($H15 / 1000) * AC$10 * $BN$4 * 0.25 ), 0 ) + IF( $N15 < 0.875, MAX(0, MIN(($H15 / 1000) * AC$10 * $BN$4, AC$11 * 0.876) - (AC$11 * $N15)) * 0.25, 0 )} -> 0 | AD15: =SUM(TabellaMar2026[[#This Row],[Colonna24]:[Colonna20]]) -> 0 | AE15: =IF( AND($H15 > $BN$7, Tabella01MarzoInverter[[#This Row],[Active power TX2-INV-1]] <= 0, Tabella01MarzoInverter[[#This Row],[TX2 - Average Power]] <= 0), MIN(($H15 / 1000) * AE$10 * $BN$4, AE$11 * 0.876) * 0.25, IF( AND($H15 > $BN$7, Tabella01MarzoInverter[[#This Row],[Active power TX2-INV-1]] <= 0), Tabella01MarzoInverter[[#This Row],[TX2 - Average Power]] * 0.25, 0 ) + IF( $N15 < 0.875, MAX(0, MIN(($H15 / 1000) * AE$10 * $BN$4, AE$11 * 0.876) - (AE$11 * $N15)) * 0.25, 0 ) ) -> 0 | AF15: =IF( AND($H15 > $BN$7, Tabella01MarzoInverter[[#This Row],[Active power TX2-INV-2]] <= 0, Tabella01MarzoInverter[[#This Row],[TX2 - Max Power]] <= 0), MIN(($H15 / 1000) * AF$10 * $BN$4, AF$11 * 0.876) * 0.25, IF( AND($H15 > $BN$7, Tabella01MarzoInverter[[#This Row],[Active power TX2-INV-2]] <= 0), Tabella01MarzoInverter[[#This Row],[TX2 - Max Power]] * 0.25, 0 ) + IF( $N15 < 0.875, MAX(0, MIN(($H15 / 1000) * AF$10 * $BN$4, AF$11 * 0.876) - (AF$11 * $N15)) * 0.25, 0 ) ) -> 0 | AG15: =IF( AND($H15 > $BN$7, Tabella01MarzoInverter[[#This Row],[Active power TX2-INV-3]] <= 0, Tabella01MarzoInverter[[#This Row],[TX2 - Min Power]] <= 0), MIN(($H15 / 1000) * AG$10 * $BN$4, AG$11 * 0.876) * 0.25, IF( AND($H15 > $BN$7, Tabella01MarzoInverter[[#This Row],[Active power TX2-INV-3]] <= 0), Tabella01MarzoInverter[[#This Row],[TX2 - Min Power]] * 0.25, 0 ) + IF( $N15 < 0.875, MAX(0, MIN(($H15 / 1000) * AG$10 * $BN$4, AG$11 * 0.876) - (AG$11 * $N15)) * 0.25, 0 ) ) -> 0 | AH15: =IF( AND($H15 > $BN$7, Tabella01MarzoInverter[[#This Row],[Active power TX2-INV-4]] <= 0, Tabella01MarzoInverter[[#This Row],[Active power TX3-INV-1]] <= 0), MIN(($H15 / 1000) * AH$10 * $BN$4, AH$11 * 0.876) * 0.25, IF( AND($H15 > $BN$7, Tabella01MarzoInverter[[#This Row],[Active power TX2-INV-4]] <= 0), Tabella01MarzoInverter[[#This Row],[Active power TX3-INV-1]] * 0.25, 0 ) + IF( $N15 < 0.875, MAX(0, MIN(($H15 / 1000) * AH$10 * $BN$4, AH$11 * 0.876) - (AH$11 * $N15)) * 0.25, 0 ) ) -> 0 | AI15: =IF( AND($H15 > $BN$7, Tabella01MarzoInverter[[#This Row],[Active power TX2-INV-5]] <= 0, Tabella01MarzoInverter[[#This Row],[Active power TX3-INV-2]] <= 0), MIN(($H15 / 1000) * AI$10 * $BN$4, AI$11 * 0.876) * 0.25, IF( AND($H15 > $BN$7, Tabella01MarzoInverter[[#This Row],[Active power TX2-INV-5]] <= 0), Tabella01MarzoInverter[[#This Row],[Active power TX3-INV-2]] * 0.25, 0 ) + IF( $N15 < 0.875, MAX(0, MIN(($H15 / 1000) * AI$10 * $BN$4, AI$11 * 0.876) - (AI$11 * $N15)) * 0.25, 0 ) ) -> 0 | AJ15: =IF( AND($H15 > $BN$7, Tabella01MarzoInverter[[#This Row],[Active power TX2-INV-6]] <= 0, Tabella01MarzoInverter[[#This Row],[Active power TX3-INV-3]] <= 0), MIN(($H15 / 1000) * AJ$10 * $BN$4, AJ$11 * 0.876) * 0.25, IF( AND($H15 > $BN$7, Tabella01MarzoInverter[[#This Row],[Active power TX2-INV-6]] <= 0), Tabella01MarzoInverter[[#This Row],[Active power TX3-INV-3]] * 0.25, 0 ) + IF( $N15 < 0.875, MAX(0, MIN(($H15 / 1000) * AJ$10 * $BN$4, AJ$11 * 0.876) - (AJ$11 * $N15)) * 0.25, 0 ) ) -> 0 | AK15: =IF( AND($H15 > $BN$7, Tabella01MarzoInverter[[#This Row],[Active power TX2-INV-7]] <= 0, Tabella01MarzoInverter[[#This Row],[Active power TX3-INV-4]] <= 0), MIN(($H15 / 1000) * AK$10 * $BN$4, AK$11 * 0.876) * 0.25, IF( AND($H15 > $BN$7, Tabella01MarzoInverter[[#This Row],[Active power TX2-INV-7]] <= 0), Tabella01MarzoInverter[[#This Row],[Active power TX3-INV-4]] * 0.25, 0 ) + IF( $N15 < 0.875, MAX(0, MIN(($H15 / 1000) * AK$10 * $BN$4, AK$11 * 0.876) - (AK$11 * $N15)) * 0.25, 0 ) ) -> 0 | AL15: =IF( AND($H15 > $BN$7, Tabella01MarzoInverter[[#This Row],[Active power TX2-INV-8]] <= 0, Tabella01MarzoInverter[[#This Row],[Active power TX3-INV-5]] <= 0), MIN(($H15 / 1000) * AL$10 * $BN$4, AL$11 * 0.876) * 0.25, IF( AND($H15 > $BN$7, Tabella01MarzoInverter[[#This Row],[Active power TX2-INV-8]] <= 0), Tabella01MarzoInverter[[#This Row],[Active power TX3-INV-5]] * 0.25, 0 ) + IF( $N15 < 0.875, MAX(0, MIN(($H15 / 1000) * AL$10 * $BN$4, AL$11 * 0.876) - (AL$11 * $N15)) * 0.25, 0 ) ) -> 0 | AM15: =IF( AND($H15 > $BN$7, Tabella01MarzoInverter[[#This Row],[Active power TX2-INV-9]] <= 0, Tabella01MarzoInverter[[#This Row],[Active power TX3-INV-6]] <= 0), MIN(($H15 / 1000) * AM$10 * $BN$4, AM$11 * 0.876) * 0.25, IF( AND($H15 > $BN$7, Tabella01MarzoInverter[[#This Row],[Active power TX2-INV-9]] <= 0), Tabella01MarzoInverter[[#This Row],[Active power TX3-INV-6]] * 0.25, 0 ) + IF( $N15 < 0.875, MAX(0, MIN(($H15 / 1000) * AM$10 * $BN$4, AM$11 * 0.876) - (AM$11 * $N15)) * 0.25, 0 ) ) -> 0 | AN15: =IF( AND($H15 > $BN$7, Tabella01MarzoInverter[[#This Row],[Active power TX2-INV-10]] <= 0, Tabella01MarzoInverter[[#This Row],[Active power TX3-INV-7]] <= 0), MIN(($H15 / 1000) * AN$10 * $BN$4, AN$11 * 0.876) * 0.25, IF( AND($H15 > $BN$7, Tabella01MarzoInverter[[#This Row],[Active power TX2-INV-10]] <= 0), Tabella01MarzoInverter[[#This Row],[Active power TX3-INV-7]] * 0.25, 0 ) + IF( $N15 < 0.875, MAX(0, MIN(($H15 / 1000) * AN$10 * $BN$4, AN$11 * 0.876) - (AN$11 * $N15)) * 0.25, 0 ) ) -> 0 | AO15: =IF( AND($H15 > $BN$7, Tabella01MarzoInverter[[#This Row],[Active power TX2-INV-11]] <= 0, Tabella01MarzoInverter[[#This Row],[Active power TX3-INV-8]] <= 0), MIN(($H15 / 1000) * AO$10 * $BN$4, AO$11 * 0.876) * 0.25, IF( AND($H15 > $BN$7, Tabella01MarzoInverter[[#This Row],[Active power TX2-INV-11]] <= 0), Tabella01MarzoInverter[[#This Row],[Active power TX3-INV-8]] * 0.25, 0 ) + IF( $N15 < 0.875, MAX(0, MIN(($H15 / 1000) * AO$10 * $BN$4, AO$11 * 0.876) - (AO$11 * $N15)) * 0.25, 0 ) ) -> 0 | AP15: =IF( AND($H15 > $BN$7, Tabella01MarzoInverter[[#This Row],[Active power TX2-INV-12]] <= 0, Tabella01MarzoInverter[[#This Row],[Active power TX3-INV-9]] <= 0), MIN(($H15 / 1000) * AP$10 * $BN$4, AP$11 * 0.876) * 0.25, IF( AND($H15 > $BN$7, Tabella01MarzoInverter[[#This Row],[Active power TX2-INV-12]] <= 0), Tabella01MarzoInverter[[#This Row],[Active power TX3-INV-9]] * 0.25, 0 ) + IF( $N15 < 0.875, MAX(0, MIN(($H15 / 1000) * AP$10 * $BN$4, AP$11 * 0.876) - (AP$11 * $N15)) * 0.25, 0 ) ) -> 0 | AQ15: =AVERAGE(TabellaMar2026[[#This Row],[Colonna39]:[Colonna6]]) -> 0 | AR15: =MAX(TabellaMar2026[[#This Row],[Colonna39]:[Colonna6]]) -> 0 | AS15: =MIN(TabellaMar2026[[#This Row],[Colonna39]:[Colonna6]]) -> 0 | AT15: =SUM(TabellaMar2026[[#This Row],[Colonna39]:[Colonna6]]) -> 0 | AU15: {=IF( AND($H15 > $BN$7, Tabella01MarzoInverter[[#This Row],[Active power TX3-INV-1]] <= 0), IF( Tabella01MarzoInverter[[#This Row],[TX3 - Average Power]:[TX3 - Average Power]] > 0, Tabella01MarzoInverter[[#This Row],[TX3 - Average Power]:[TX3 - Average Power]] * 0.25, ($H15 / 1000) * AU$10 * $BN$4 * 0.25 ), 0 ) + IF( $N15 < 0.875, MAX(0, MIN(($H15 / 1000) * AU$10 * $BN$4, AU$11 * 0.876) - (AU$11 * $N15)) * 0.25, 0 )} -> 0 | AV15: {=IF( AND($H15 > $BN$7, Tabella01MarzoInverter[[#This Row],[Active power TX3-INV-2]] <= 0), IF( Tabella01MarzoInverter[[#This Row],[TX3 - Average Power]:[TX3 - Average Power]] > 0, Tabella01MarzoInverter[[#This Row],[TX3 - Average Power]:[TX3 - Average Power]] * 0.25, ($H15 / 1000) * AV$10 * $BN$4 * 0.25 ), 0 ) + IF( $N15 < 0.875, MAX(0, MIN(($H15 / 1000) * AV$10 * $BN$4, AV$11 * 0.876) - (AV$11 * $N15)) * 0.25, 0 )} -> 0 | AW15: {=IF( AND($H15 > $BN$7, Tabella01MarzoInverter[[#This Row],[Active power TX3-INV-3]] <= 0), IF( Tabella01MarzoInverter[[#This Row],[TX3 - Average Power]:[TX3 - Average Power]] > 0, Tabella01MarzoInverter[[#This Row],[TX3 - Average Power]:[TX3 - Average Power]] * 0.25, ($H15 / 1000) * AW$10 * $BN$4 * 0.25 ), 0 ) + IF( $N15 < 0.875, MAX(0, MIN(($H15 / 1000) * AW$10 * $BN$4, AW$11 * 0.876) - (AW$11 * $N15)) * 0.25, 0 )} -> 0 | AX15: {=IF( AND($H15 > $BN$7, Tabella01MarzoInverter[[#This Row],[Active power TX3-INV-4]] <= 0), IF( Tabella01MarzoInverter[[#This Row],[TX3 - Average Power]:[TX3 - Average Power]] > 0, Tabella01MarzoInverter[[#This Row],[TX3 - Average Power]:[TX3 - Average Power]] * 0.25, ($H15 / 1000) * AX$10 * $BN$4 * 0.25 ), 0 ) + IF( $N15 < 0.875, MAX(0, MIN(($H15 / 1000) * AX$10 * $BN$4, AX$11 * 0.876) - (AX$11 * $N15)) * 0.25, 0 )} -> 0 | AY15: {=IF( AND($H15 > $BN$7, Tabella01MarzoInverter[[#This Row],[Active power TX3-INV-5]] <= 0), IF( Tabella01MarzoInverter[[#This Row],[TX3 - Average Power]:[TX3 - Average Power]] > 0, Tabella01MarzoInverter[[#This Row],[TX3 - Average Power]:[TX3 - Average Power]] * 0.25, ($H15 / 1000) * AY$10 * $BN$4 * 0.25 ), 0 ) + IF( $N15 < 0.875, MAX(0, MIN(($H15 / 1000) * AY$10 * $BN$4, AY$11 * 0.876) - (AY$11 * $N15)) * 0.25, 0 )} -> 0 | AZ15: {=IF( AND($H15 > $BN$7, Tabella01MarzoInverter[[#This Row],[Active power TX3-INV-6]] <= 0), IF( Tabella01MarzoInverter[[#This Row],[TX3 - Average Power]:[TX3 - Average Power]] > 0, Tabella01MarzoInverter[[#This Row],[TX3 - Average Power]:[TX3 - Average Power]] * 0.25, ($H15 / 1000) * AZ$10 * $BN$4 * 0.25 ), 0 ) + IF( $N15 < 0.875, MAX(0, MIN(($H15 / 1000) * AZ$10 * $BN$4, AZ$11 * 0.876) - (AZ$11 * $N15)) * 0.25, 0 )} -> 0 | BA15: {=IF( AND($H15 > $BN$7, Tabella01MarzoInverter[[#This Row],[Active power TX3-INV-7]] <= 0), IF( Tabella01MarzoInverter[[#This Row],[TX3 - Average Power]:[TX3 - Average Power]] > 0, Tabella01MarzoInverter[[#This Row],[TX3 - Average Power]:[TX3 - Average Power]] * 0.25, ($H15 / 1000) * BA$10 * $BN$4 * 0.25 ), 0 ) + IF( $N15 < 0.875, MAX(0, MIN(($H15 / 1000) * BA$10 * $BN$4, BA$11 * 0.876) - (BA$11 * $N15)) * 0.25, 0 )} -> 0 | BB15: {=IF( AND($H15 > $BN$7, Tabella01MarzoInverter[[#This Row],[Active power TX3-INV-8]] <= 0), IF( Tabella01MarzoInverter[[#This Row],[TX3 - Average Power]:[TX3 - Average Power]] > 0, Tabella01MarzoInverter[[#This Row],[TX3 - Average Power]:[TX3 - Average Power]] * 0.25, ($H15 / 1000) * BB$10 * $BN$4 * 0.25 ), 0 ) + IF( $N15 < 0.875, MAX(0, MIN(($H15 / 1000) * BB$10 * $BN$4, BB$11 * 0.876) - (BB$11 * $N15)) * 0.25, 0 )} -> 0 | BC15: {=IF( AND($H15 > $BN$7, Tabella01MarzoInverter[[#This Row],[Active power TX3-INV-9]] <= 0), IF( Tabella01MarzoInverter[[#This Row],[TX3 - Average Power]:[TX3 - Average Power]] > 0, Tabella01MarzoInverter[[#This Row],[TX3 - Average Power]:[TX3 - Average Power]] * 0.25, ($H15 / 1000) * BC$10 * $BN$4 * 0.25 ), 0 ) + IF( $N15 < 0.875, MAX(0, MIN(($H15 / 1000) * BC$10 * $BN$4, BC$11 * 0.876) - (BC$11 * $N15)) * 0.25, 0 )} -> 0 | BD15: {=IF( AND($H15 > $BN$7, Tabella01MarzoInverter[[#This Row],[Active power TX3-INV-10]] <= 0), IF( Tabella01MarzoInverter[[#This Row],[TX3 - Average Power]:[TX3 - Average Power]] > 0, Tabella01MarzoInverter[[#This Row],[TX3 - Average Power]:[TX3 - Average Power]] * 0.25, ($H15 / 1000) * BD$10 * $BN$4 * 0.25 ), 0 ) + IF( $N15 < 0.875, MAX(0, MIN(($H15 / 1000) * BD$10 * $BN$4, BD$11 * 0.876) - (BD$11 * $N15)) * 0.25, 0 )} -> 0 | BE15: {=IF( AND($H15 > $BN$7, Tabella01MarzoInverter[[#This Row],[Active power TX3-INV-11]] <= 0), IF( Tabella01MarzoInverter[[#This Row],[TX3 - Average Power]:[TX3 - Average Power]] > 0, Tabella01MarzoInverter[[#This Row],[TX3 - Average Power]:[TX3 - Average Power]] * 0.25, ($H15 / 1000) * BE$10 * $BN$4 * 0.25 ), 0 ) + IF( $N15 < 0.875, MAX(0, MIN(($H15 / 1000) * BE$10 * $BN$4, BE$11 * 0.876) - (BE$11 * $N15)) * 0.25, 0 )} -> 0 | BF15: {=IF( AND($H15 > $BN$7, Tabella01MarzoInverter[[#This Row],[Active power TX3-INV-12]] <= 0), IF( Tabella01MarzoInverter[[#This Row],[TX3 - Average Power]:[TX3 - Average Power]] > 0, Tabella01MarzoInverter[[#This Row],[TX3 - Average Power]:[TX3 - Average Power]] * 0.25, ($H15 / 1000) * BF$10 * $BN$4 * 0.25 ), 0 ) + IF( $N15 < 0.875, MAX(0, MIN(($H15 / 1000) * BF$10 * $BN$4, BF$11 * 0.876) - (BF$11 * $N15)) * 0.25, 0 )} -> 0 | BG15: =AVERAGE(TabellaMar2026[[#This Row],[Colonna55]:[Colonna53]]) -> 0 | BH15: =MAX(TabellaMar2026[[#This Row],[Colonna55]:[Colonna53]]) -> 0 | BI15: =MIN(TabellaMar2026[[#This Row],[Colonna55]:[Colonna53]]) -> 0 | BJ15: =SUM(TabellaMar2026[[#This Row],[Colonna54]:[Colonna53]]) -> 0 | BK15: =IFERROR((SUM(Tabella01MarzoInverter[[Active power TX1-INV-1]:[Active power TX3-INV-12]]) * 0.25) / (12625 * (IF(TabellaMar2026[[#This Row],[Colonna67]]>BN7,TabellaMar2026[[#This Row],[Colonna67]],0) * 0.25 / 1000)),0) -> 0 | BM15: =SUM(Tabella01MarzoInverter[Active power TX1-INV-1]) -> 9197.1
A16: 46147 | B16: 00:15:00.000 | C16: -1 | D16: -0.00025 | E16: 0 | F16: 0 | G16: =IFERROR((D16+F16)/2, 0) -> -0.000125 | H16: =IFERROR(IF(AVERAGE(C16,E16)>$BN$7,AVERAGE(C16,E16),0), 0) -> 0 | I16: =IFERROR(IF(AND(D16=0,F16=0),0,IF(H16>$BN$6,MAX(D16,F16),G16)), 0) -> -0.000125 | J16: =IFERROR(IF(AND(D16>0,F16>0),ABS(D16-F16)/AVERAGE(D16,F16),0), 0) -> 0 | K16: 30386.2 | L16: 30386.2 | M16: =IFERROR((L16-K16)*1000, 0) -> 0 | N16: 0.876 | O16: {=IF( AND($H16 > $BN$7, Tabella01MarzoInverter[[#This Row],[Active power TX1-INV-1]] <= 0), IF( Tabella01MarzoInverter[[#This Row],[TX1 - Average Power]:[TX1 - Average Power]] > 0, Tabella01MarzoInverter[[#This Row],[TX1 - Average Power]:[TX1 - Average Power]] * 0.25, ($H16 / 1000) * O$10 * $BN$4 * 0.25 ), 0 ) + IF( $N16 < 0.875, MAX(0, MIN(($H16 / 1000) * O$10 * $BN$4, O$11 * 0.876) - (O$11 * $N16)) * 0.25, 0 )} -> 0 | P16: {=IF( AND($H16 > $BN$7, Tabella01MarzoInverter[[#This Row],[Active power TX1-INV-2]] <= 0), IF( Tabella01MarzoInverter[[#This Row],[TX1 - Average Power]:[TX1 - Average Power]] > 0, Tabella01MarzoInverter[[#This Row],[TX1 - Average Power]:[TX1 - Average Power]] * 0.25, ($H16 / 1000) * P$10 * $BN$4 * 0.25 ), 0 ) + IF( $N16 < 0.875, MAX(0, MIN(($H16 / 1000) * P$10 * $BN$4, P$11 * 0.876) - (P$11 * $N16)) * 0.25, 0 )} -> 0 | Q16: {=IF( AND($H16 > $BN$7, Tabella01MarzoInverter[[#This Row],[Active power TX1-INV-3]] <= 0), IF( Tabella01MarzoInverter[[#This Row],[TX1 - Average Power]:[TX1 - Average Power]] > 0, Tabella01MarzoInverter[[#This Row],[TX1 - Average Power]:[TX1 - Average Power]] * 0.25, ($H16 / 1000) * Q$10 * $BN$4 * 0.25 ), 0 ) + IF( $N16 < 0.875, MAX(0, MIN(($H16 / 1000) * Q$10 * $BN$4, Q$11 * 0.876) - (Q$11 * $N16)) * 0.25, 0 )} -> 0 | R16: {=IF( AND($H16 > $BN$7, Tabella01MarzoInverter[[#This Row],[Active power TX1-INV-4]] <= 0), IF( Tabella01MarzoInverter[[#This Row],[TX1 - Average Power]:[TX1 - Average Power]] > 0, Tabella01MarzoInverter[[#This Row],[TX1 - Average Power]:[TX1 - Average Power]] * 0.25, ($H16 / 1000) * R$10 * $BN$4 * 0.25 ), 0 ) + IF( $N16 < 0.875, MAX(0, MIN(($H16 / 1000) * R$10 * $BN$4, R$11 * 0.876) - (R$11 * $N16)) * 0.25, 0 )} -> 0 | S16: {=IF( AND($H16 > $BN$7, Tabella01MarzoInverter[[#This Row],[Active power TX1-INV-5]] <= 0), IF( Tabella01MarzoInverter[[#This Row],[TX1 - Average Power]:[TX1 - Average Power]] > 0, Tabella01MarzoInverter[[#This Row],[TX1 - Average Power]:[TX1 - Average Power]] * 0.25, ($H16 / 1000) * S$10 * $BN$4 * 0.25 ), 0 ) + IF( $N16 < 0.875, MAX(0, MIN(($H16 / 1000) * S$10 * $BN$4, S$11 * 0.876) - (S$11 * $N16)) * 0.25, 0 )} -> 0 | T16: {=IF( AND($H16 > $BN$7, Tabella01MarzoInverter[[#This Row],[Active power TX1-INV-6]] <= 0), IF( Tabella01MarzoInverter[[#This Row],[TX1 - Average Power]:[TX1 - Average Power]] > 0, Tabella01MarzoInverter[[#This Row],[TX1 - Average Power]:[TX1 - Average Power]] * 0.25, ($H16 / 1000) * T$10 * $BN$4 * 0.25 ), 0 ) + IF( $N16 < 0.875, MAX(0, MIN(($H16 / 1000) * T$10 * $BN$4, T$11 * 0.876) - (T$11 * $N16)) * 0.25, 0 )} -> 0 | U16: {=IF( AND($H16 > $BN$7, Tabella01MarzoInverter[[#This Row],[Active power TX1-INV-7]] <= 0), IF( Tabella01MarzoInverter[[#This Row],[TX1 - Average Power]:[TX1 - Average Power]] > 0, Tabella01MarzoInverter[[#This Row],[TX1 - Average Power]:[TX1 - Average Power]] * 0.25, ($H16 / 1000) * U$10 * $BN$4 * 0.25 ), 0 ) + IF( $N16 < 0.875, MAX(0, MIN(($H16 / 1000) * U$10 * $BN$4, U$11 * 0.876) - (U$11 * $N16)) * 0.25, 0 )} -> 0 | V16: {=IF( AND($H16 > $BN$7, Tabella01MarzoInverter[[#This Row],[Active power TX1-INV-8]] <= 0), IF( Tabella01MarzoInverter[[#This Row],[TX1 - Average Power]:[TX1 - Average Power]] > 0, Tabella01MarzoInverter[[#This Row],[TX1 - Average Power]:[TX1 - Average Power]] * 0.25, ($H16 / 1000) * V$10 * $BN$4 * 0.25 ), 0 ) + IF( $N16 < 0.875, MAX(0, MIN(($H16 / 1000) * V$10 * $BN$4, V$11 * 0.876) - (V$11 * $N16)) * 0.25, 0 )} -> 0 | W16: {=IF( AND($H16 > $BN$7, Tabella01MarzoInverter[[#This Row],[Active power TX1-INV-9]] <= 0), IF( Tabella01MarzoInverter[[#This Row],[TX1 - Average Power]:[TX1 - Average Power]] > 0, Tabella01MarzoInverter[[#This Row],[TX1 - Average Power]:[TX1 - Average Power]] * 0.25, ($H16 / 1000) * W$10 * $BN$4 * 0.25 ), 0 ) + IF( $N16 < 0.875, MAX(0, MIN(($H16 / 1000) * W$10 * $BN$4, W$11 * 0.876) - (W$11 * $N16)) * 0.25, 0 )} -> 0 | X16: {=IF( AND($H16 > $BN$7, Tabella01MarzoInverter[[#This Row],[Active power TX1-INV-10]] <= 0), IF( Tabella01MarzoInverter[[#This Row],[TX1 - Average Power]:[TX1 - Average Power]] > 0, Tabella01MarzoInverter[[#This Row],[TX1 - Average Power]:[TX1 - Average Power]] * 0.25, ($H16 / 1000) * X$10 * $BN$4 * 0.25 ), 0 ) + IF( $N16 < 0.875, MAX(0, MIN(($H16 / 1000) * X$10 * $BN$4, X$11 * 0.876) - (X$11 * $N16)) * 0.25, 0 )} -> 0 | Y16: {=IF( AND($H16 > $BN$7, Tabella01MarzoInverter[[#This Row],[Active power TX1-INV-11]] <= 0), IF( Tabella01MarzoInverter[[#This Row],[TX1 - Average Power]:[TX1 - Average Power]] > 0, Tabella01MarzoInverter[[#This Row],[TX1 - Average Power]:[TX1 - Average Power]] * 0.25, ($H16 / 1000) * Y$10 * $BN$4 * 0.25 ), 0 ) + IF( $N16 < 0.875, MAX(0, MIN(($H16 / 1000) * Y$10 * $BN$4, Y$11 * 0.876) - (Y$11 * $N16)) * 0.25, 0 )} -> 0 | Z16: {=IF( AND($H16 > $BN$7, Tabella01MarzoInverter[[#This Row],[Active power TX1-INV-12]] <= 0), IF( Tabella01MarzoInverter[[#This Row],[TX1 - Average Power]:[TX1 - Average Power]] > 0, Tabella01MarzoInverter[[#This Row],[TX1 - Average Power]:[TX1 - Average Power]] * 0.25, ($H16 / 1000) * Z$10 * $BN$4 * 0.25 ), 0 ) + IF( $N16 < 0.875, MAX(0, MIN(($H16 / 1000) * Z$10 * $BN$4, Z$11 * 0.876) - (Z$11 * $N16)) * 0.25, 0 )} -> 0 | AA16: =AVERAGE(TabellaMar2026[[#This Row],[Colonna24]:[Colonna20]]) -> 0 | AB16: =MAX(TabellaMar2026[[#This Row],[Colonna24]:[Colonna20]]) -> 0 | AC16: =MIN(TabellaMar2026[[#This Row],[Colonna24]:[Colonna20]]) -> 0 | AD16: =SUM(TabellaMar2026[[#This Row],[Colonna24]:[Colonna20]]) -> 0 | AE16: =IF( AND($H16 > $BN$7, Tabella01MarzoInverter[[#This Row],[Active power TX2-INV-1]] <= 0, Tabella01MarzoInverter[[#This Row],[TX2 - Average Power]] <= 0), MIN(($H16 / 1000) * AE$10 * $BN$4, AE$11 * 0.876) * 0.25, IF( AND($H16 > $BN$7, Tabella01MarzoInverter[[#This Row],[Active power TX2-INV-1]] <= 0), Tabella01MarzoInverter[[#This Row],[TX2 - Average Power]] * 0.25, 0 ) + IF( $N16 < 0.875, MAX(0, MIN(($H16 / 1000) * AE$10 * $BN$4, AE$11 * 0.876) - (AE$11 * $N16)) * 0.25, 0 ) ) -> 0 | AF16: =IF( AND($H16 > $BN$7, Tabella01MarzoInverter[[#This Row],[Active power TX2-INV-2]] <= 0, Tabella01MarzoInverter[[#This Row],[TX2 - Max Power]] <= 0), MIN(($H16 / 1000) * AF$10 * $BN$4, AF$11 * 0.876) * 0.25, IF( AND($H16 > $BN$7, Tabella01MarzoInverter[[#This Row],[Active power TX2-INV-2]] <= 0), Tabella01MarzoInverter[[#This Row],[TX2 - Max Power]] * 0.25, 0 ) + IF( $N16 < 0.875, MAX(0, MIN(($H16 / 1000) * AF$10 * $BN$4, AF$11 * 0.876) - (AF$11 * $N16)) * 0.25, 0 ) ) -> 0 | AG16: =IF( AND($H16 > $BN$7, Tabella01MarzoInverter[[#This Row],[Active power TX2-INV-3]] <= 0, Tabella01MarzoInverter[[#This Row],[TX2 - Min Power]] <= 0), MIN(($H16 / 1000) * AG$10 * $BN$4, AG$11 * 0.876) * 0.25, IF( AND($H16 > $BN$7, Tabella01MarzoInverter[[#This Row],[Active power TX2-INV-3]] <= 0), Tabella01MarzoInverter[[#This Row],[TX2 - Min Power]] * 0.25, 0 ) + IF( $N16 < 0.875, MAX(0, MIN(($H16 / 1000) * AG$10 * $BN$4, AG$11 * 0.876) - (AG$11 * $N16)) * 0.25, 0 ) ) -> 0 | AH16: =IF( AND($H16 > $BN$7, Tabella01MarzoInverter[[#This Row],[Active power TX2-INV-4]] <= 0, Tabella01MarzoInverter[[#This Row],[Active power TX3-INV-1]] <= 0), MIN(($H16 / 1000) * AH$10 * $BN$4, AH$11 * 0.876) * 0.25, IF( AND($H16 > $BN$7, Tabella01MarzoInverter[[#This Row],[Active power TX2-INV-4]] <= 0), Tabella01MarzoInverter[[#This Row],[Active power TX3-INV-1]] * 0.25, 0 ) + IF( $N16 < 0.875, MAX(0, MIN(($H16 / 1000) * AH$10 * $BN$4, AH$11 * 0.876) - (AH$11 * $N16)) * 0.25, 0 ) ) -> 0 | AI16: =IF( AND($H16 > $BN$7, Tabella01MarzoInverter[[#This Row],[Active power TX2-INV-5]] <= 0, Tabella01MarzoInverter[[#This Row],[Active power TX3-INV-2]] <= 0), MIN(($H16 / 1000) * AI$10 * $BN$4, AI$11 * 0.876) * 0.25, IF( AND($H16 > $BN$7, Tabella01MarzoInverter[[#This Row],[Active power TX2-INV-5]] <= 0), Tabella01MarzoInverter[[#This Row],[Active power TX3-INV-2]] * 0.25, 0 ) + IF( $N16 < 0.875, MAX(0, MIN(($H16 / 1000) * AI$10 * $BN$4, AI$11 * 0.876) - (AI$11 * $N16)) * 0.25, 0 ) ) -> 0 | AJ16: =IF( AND($H16 > $BN$7, Tabella01MarzoInverter[[#This Row],[Active power TX2-INV-6]] <= 0, Tabella01MarzoInverter[[#This Row],[Active power TX3-INV-3]] <= 0), MIN(($H16 / 1000) * AJ$10 * $BN$4, AJ$11 * 0.876) * 0.25, IF( AND($H16 > $BN$7, Tabella01MarzoInverter[[#This Row],[Active power TX2-INV-6]] <= 0), Tabella01MarzoInverter[[#This Row],[Active power TX3-INV-3]] * 0.25, 0 ) + IF( $N16 < 0.875, MAX(0, MIN(($H16 / 1000) * AJ$10 * $BN$4, AJ$11 * 0.876) - (AJ$11 * $N16)) * 0.25, 0 ) ) -> 0 | AK16: =IF( AND($H16 > $BN$7, Tabella01MarzoInverter[[#This Row],[Active power TX2-INV-7]] <= 0, Tabella01MarzoInverter[[#This Row],[Active power TX3-INV-4]] <= 0), MIN(($H16 / 1000) * AK$10 * $BN$4, AK$11 * 0.876) * 0.25, IF( AND($H16 > $BN$7, Tabella01MarzoInverter[[#This Row],[Active power TX2-INV-7]] <= 0), Tabella01MarzoInverter[[#This Row],[Active power TX3-INV-4]] * 0.25, 0 ) + IF( $N16 < 0.875, MAX(0, MIN(($H16 / 1000) * AK$10 * $BN$4, AK$11 * 0.876) - (AK$11 * $N16)) * 0.25, 0 ) ) -> 0 | AL16: =IF( AND($H16 > $BN$7, Tabella01MarzoInverter[[#This Row],[Active power TX2-INV-8]] <= 0, Tabella01MarzoInverter[[#This Row],[Active power TX3-INV-5]] <= 0), MIN(($H16 / 1000) * AL$10 * $BN$4, AL$11 * 0.876) * 0.25, IF( AND($H16 > $BN$7, Tabella01MarzoInverter[[#This Row],[Active power TX2-INV-8]] <= 0), Tabella01MarzoInverter[[#This Row],[Active power TX3-INV-5]] * 0.25, 0 ) + IF( $N16 < 0.875, MAX(0, MIN(($H16 / 1000) * AL$10 * $BN$4, AL$11 * 0.876) - (AL$11 * $N16)) * 0.25, 0 ) ) -> 0 | AM16: =IF( AND($H16 > $BN$7, Tabella01MarzoInverter[[#This Row],[Active power TX2-INV-9]] <= 0, Tabella01MarzoInverter[[#This Row],[Active power TX3-INV-6]] <= 0), MIN(($H16 / 1000) * AM$10 * $BN$4, AM$11 * 0.876) * 0.25, IF( AND($H16 > $BN$7, Tabella01MarzoInverter[[#This Row],[Active power TX2-INV-9]] <= 0), Tabella01MarzoInverter[[#This Row],[Active power TX3-INV-6]] * 0.25, 0 ) + IF( $N16 < 0.875, MAX(0, MIN(($H16 / 1000) * AM$10 * $BN$4, AM$11 * 0.876) - (AM$11 * $N16)) * 0.25, 0 ) ) -> 0 | AN16: =IF( AND($H16 > $BN$7, Tabella01MarzoInverter[[#This Row],[Active power TX2-INV-10]] <= 0, Tabella01MarzoInverter[[#This Row],[Active power TX3-INV-7]] <= 0), MIN(($H16 / 1000) * AN$10 * $BN$4, AN$11 * 0.876) * 0.25, IF( AND($H16 > $BN$7, Tabella01MarzoInverter[[#This Row],[Active power TX2-INV-10]] <= 0), Tabella01MarzoInverter[[#This Row],[Active power TX3-INV-7]] * 0.25, 0 ) + IF( $N16 < 0.875, MAX(0, MIN(($H16 / 1000) * AN$10 * $BN$4, AN$11 * 0.876) - (AN$11 * $N16)) * 0.25, 0 ) ) -> 0 | AO16: =IF( AND($H16 > $BN$7, Tabella01MarzoInverter[[#This Row],[Active power TX2-INV-11]] <= 0, Tabella01MarzoInverter[[#This Row],[Active power TX3-INV-8]] <= 0), MIN(($H16 / 1000) * AO$10 * $BN$4, AO$11 * 0.876) * 0.25, IF( AND($H16 > $BN$7, Tabella01MarzoInverter[[#This Row],[Active power TX2-INV-11]] <= 0), Tabella01MarzoInverter[[#This Row],[Active power TX3-INV-8]] * 0.25, 0 ) + IF( $N16 < 0.875, MAX(0, MIN(($H16 / 1000) * AO$10 * $BN$4, AO$11 * 0.876) - (AO$11 * $N16)) * 0.25, 0 ) ) -> 0 | AP16: =IF( AND($H16 > $BN$7, Tabella01MarzoInverter[[#This Row],[Active power TX2-INV-12]] <= 0, Tabella01MarzoInverter[[#This Row],[Active power TX3-INV-9]] <= 0), MIN(($H16 / 1000) * AP$10 * $BN$4, AP$11 * 0.876) * 0.25, IF( AND($H16 > $BN$7, Tabella01MarzoInverter[[#This Row],[Active power TX2-INV-12]] <= 0), Tabella01MarzoInverter[[#This Row],[Active power TX3-INV-9]] * 0.25, 0 ) + IF( $N16 < 0.875, MAX(0, MIN(($H16 / 1000) * AP$10 * $BN$4, AP$11 * 0.876) - (AP$11 * $N16)) * 0.25, 0 ) ) -> 0 | AQ16: =AVERAGE(TabellaMar2026[[#This Row],[Colonna39]:[Colonna6]]) -> 0 | AR16: =MAX(TabellaMar2026[[#This Row],[Colonna39]:[Colonna6]]) -> 0 | AS16: =MIN(TabellaMar2026[[#This Row],[Colonna39]:[Colonna6]]) -> 0 | AT16: =SUM(TabellaMar2026[[#This Row],[Colonna39]:[Colonna6]]) -> 0 | AU16: {=IF( AND($H16 > $BN$7, Tabella01MarzoInverter[[#This Row],[Active power TX3-INV-1]] <= 0), IF( Tabella01MarzoInverter[[#This Row],[TX3 - Average Power]:[TX3 - Average Power]] > 0, Tabella01MarzoInverter[[#This Row],[TX3 - Average Power]:[TX3 - Average Power]] * 0.25, ($H16 / 1000) * AU$10 * $BN$4 * 0.25 ), 0 ) + IF( $N16 < 0.875, MAX(0, MIN(($H16 / 1000) * AU$10 * $BN$4, AU$11 * 0.876) - (AU$11 * $N16)) * 0.25, 0 )} -> 0 | AV16: {=IF( AND($H16 > $BN$7, Tabella01MarzoInverter[[#This Row],[Active power TX3-INV-2]] <= 0), IF( Tabella01MarzoInverter[[#This Row],[TX3 - Average Power]:[TX3 - Average Power]] > 0, Tabella01MarzoInverter[[#This Row],[TX3 - Average Power]:[TX3 - Average Power]] * 0.25, ($H16 / 1000) * AV$10 * $BN$4 * 0.25 ), 0 ) + IF( $N16 < 0.875, MAX(0, MIN(($H16 / 1000) * AV$10 * $BN$4, AV$11 * 0.876) - (AV$11 * $N16)) * 0.25, 0 )} -> 0 | AW16: {=IF( AND($H16 > $BN$7, Tabella01MarzoInverter[[#This Row],[Active power TX3-INV-3]] <= 0), IF( Tabella01MarzoInverter[[#This Row],[TX3 - Average Power]:[TX3 - Average Power]] > 0, Tabella01MarzoInverter[[#This Row],[TX3 - Average Power]:[TX3 - Average Power]] * 0.25, ($H16 / 1000) * AW$10 * $BN$4 * 0.25 ), 0 ) + IF( $N16 < 0.875, MAX(0, MIN(($H16 / 1000) * AW$10 * $BN$4, AW$11 * 0.876) - (AW$11 * $N16)) * 0.25, 0 )} -> 0 | AX16: {=IF( AND($H16 > $BN$7, Tabella01MarzoInverter[[#This Row],[Active power TX3-INV-4]] <= 0), IF( Tabella01MarzoInverter[[#This Row],[TX3 - Average Power]:[TX3 - Average Power]] > 0, Tabella01MarzoInverter[[#This Row],[TX3 - Average Power]:[TX3 - Average Power]] * 0.25, ($H16 / 1000) * AX$10 * $BN$4 * 0.25 ), 0 ) + IF( $N16 < 0.875, MAX(0, MIN(($H16 / 1000) * AX$10 * $BN$4, AX$11 * 0.876) - (AX$11 * $N16)) * 0.25, 0 )} -> 0 | AY16: {=IF( AND($H16 > $BN$7, Tabella01MarzoInverter[[#This Row],[Active power TX3-INV-5]] <= 0), IF( Tabella01MarzoInverter[[#This Row],[TX3 - Average Power]:[TX3 - Average Power]] > 0, Tabella01MarzoInverter[[#This Row],[TX3 - Average Power]:[TX3 - Average Power]] * 0.25, ($H16 / 1000) * AY$10 * $BN$4 * 0.25 ), 0 ) + IF( $N16 < 0.875, MAX(0, MIN(($H16 / 1000) * AY$10 * $BN$4, AY$11 * 0.876) - (AY$11 * $N16)) * 0.25, 0 )} -> 0 | AZ16: {=IF( AND($H16 > $BN$7, Tabella01MarzoInverter[[#This Row],[Active power TX3-INV-6]] <= 0), IF( Tabella01MarzoInverter[[#This Row],[TX3 - Average Power]:[TX3 - Average Power]] > 0, Tabella01MarzoInverter[[#This Row],[TX3 - Average Power]:[TX3 - Average Power]] * 0.25, ($H16 / 1000) * AZ$10 * $BN$4 * 0.25 ), 0 ) + IF( $N16 < 0.875, MAX(0, MIN(($H16 / 1000) * AZ$10 * $BN$4, AZ$11 * 0.876) - (AZ$11 * $N16)) * 0.25, 0 )} -> 0 | BA16: {=IF( AND($H16 > $BN$7, Tabella01MarzoInverter[[#This Row],[Active power TX3-INV-7]] <= 0), IF( Tabella01MarzoInverter[[#This Row],[TX3 - Average Power]:[TX3 - Average Power]] > 0, Tabella01MarzoInverter[[#This Row],[TX3 - Average Power]:[TX3 - Average Power]] * 0.25, ($H16 / 1000) * BA$10 * $BN$4 * 0.25 ), 0 ) + IF( $N16 < 0.875, MAX(0, MIN(($H16 / 1000) * BA$10 * $BN$4, BA$11 * 0.876) - (BA$11 * $N16)) * 0.25, 0 )} -> 0 | BB16: {=IF( AND($H16 > $BN$7, Tabella01MarzoInverter[[#This Row],[Active power TX3-INV-8]] <= 0), IF( Tabella01MarzoInverter[[#This Row],[TX3 - Average Power]:[TX3 - Average Power]] > 0, Tabella01MarzoInverter[[#This Row],[TX3 - Average Power]:[TX3 - Average Power]] * 0.25, ($H16 / 1000) * BB$10 * $BN$4 * 0.25 ), 0 ) + IF( $N16 < 0.875, MAX(0, MIN(($H16 / 1000) * BB$10 * $BN$4, BB$11 * 0.876) - (BB$11 * $N16)) * 0.25, 0 )} -> 0 | BC16: {=IF( AND($H16 > $BN$7, Tabella01MarzoInverter[[#This Row],[Active power TX3-INV-9]] <= 0), IF( Tabella01MarzoInverter[[#This Row],[TX3 - Average Power]:[TX3 - Average Power]] > 0, Tabella01MarzoInverter[[#This Row],[TX3 - Average Power]:[TX3 - Average Power]] * 0.25, ($H16 / 1000) * BC$10 * $BN$4 * 0.25 ), 0 ) + IF( $N16 < 0.875, MAX(0, MIN(($H16 / 1000) * BC$10 * $BN$4, BC$11 * 0.876) - (BC$11 * $N16)) * 0.25, 0 )} -> 0 | BD16: {=IF( AND($H16 > $BN$7, Tabella01MarzoInverter[[#This Row],[Active power TX3-INV-10]] <= 0), IF( Tabella01MarzoInverter[[#This Row],[TX3 - Average Power]:[TX3 - Average Power]] > 0, Tabella01MarzoInverter[[#This Row],[TX3 - Average Power]:[TX3 - Average Power]] * 0.25, ($H16 / 1000) * BD$10 * $BN$4 * 0.25 ), 0 ) + IF( $N16 < 0.875, MAX(0, MIN(($H16 / 1000) * BD$10 * $BN$4, BD$11 * 0.876) - (BD$11 * $N16)) * 0.25, 0 )} -> 0 | BE16: {=IF( AND($H16 > $BN$7, Tabella01MarzoInverter[[#This Row],[Active power TX3-INV-11]] <= 0), IF( Tabella01MarzoInverter[[#This Row],[TX3 - Average Power]:[TX3 - Average Power]] > 0, Tabella01MarzoInverter[[#This Row],[TX3 - Average Power]:[TX3 - Average Power]] * 0.25, ($H16 / 1000) * BE$10 * $BN$4 * 0.25 ), 0 ) + IF( $N16 < 0.875, MAX(0, MIN(($H16 / 1000) * BE$10 * $BN$4, BE$11 * 0.876) - (BE$11 * $N16)) * 0.25, 0 )} -> 0 | BF16: {=IF( AND($H16 > $BN$7, Tabella01MarzoInverter[[#This Row],[Active power TX3-INV-12]] <= 0), IF( Tabella01MarzoInverter[[#This Row],[TX3 - Average Power]:[TX3 - Average Power]] > 0, Tabella01MarzoInverter[[#This Row],[TX3 - Average Power]:[TX3 - Average Power]] * 0.25, ($H16 / 1000) * BF$10 * $BN$4 * 0.25 ), 0 ) + IF( $N16 < 0.875, MAX(0, MIN(($H16 / 1000) * BF$10 * $BN$4, BF$11 * 0.876) - (BF$11 * $N16)) * 0.25, 0 )} -> 0 | BG16: =AVERAGE(TabellaMar2026[[#This Row],[Colonna55]:[Colonna53]]) -> 0 | BH16: =MAX(TabellaMar2026[[#This Row],[Colonna55]:[Colonna53]]) -> 0 | BI16: =MIN(TabellaMar2026[[#This Row],[Colonna55]:[Colonna53]]) -> 0 | BJ16: =SUM(TabellaMar2026[[#This Row],[Colonna54]:[Colonna53]]) -> 0 | BK16: =(SUM(Tabella01MarzoInverter[[Active power TX1-INV-1]:[Active power TX3-INV-12]]) * 0.25) / (12625 * (SUM($G$15:$H$110) * 0.25 / 1000)) -> 1.0142296
A17: 46147 | B17: 00:30:00.000 | C17: -1 | D17: -0.00025 | E17: 0 | F17: 0 | G17: =IFERROR((D17+F17)/2, 0) -> -0.000125 | H17: =IFERROR(IF(AVERAGE(C17,E17)>$BN$7,AVERAGE(C17,E17),0), 0) -> 0 | I17: =IFERROR(IF(AND(D17=0,F17=0),0,IF(H17>$BN$6,MAX(D17,F17),G17)), 0) -> -0.000125 | J17: =IFERROR(IF(AND(D17>0,F17>0),ABS(D17-F17)/AVERAGE(D17,F17),0), 0) -> 0 | K17: 30386.2 | L17: 30386.2 | M17: =IFERROR((L17-K17)*1000, 0) -> 0 | N17: 0.876 | O17: {=IF( AND($H17 > $BN$7, Tabella01MarzoInverter[[#This Row],[Active power TX1-INV-1]] <= 0), IF( Tabella01MarzoInverter[[#This Row],[TX1 - Average Power]:[TX1 - Average Power]] > 0, Tabella01MarzoInverter[[#This Row],[TX1 - Average Power]:[TX1 - Average Power]] * 0.25, ($H17 / 1000) * O$10 * $BN$4 * 0.25 ), 0 ) + IF( $N17 < 0.875, MAX(0, MIN(($H17 / 1000) * O$10 * $BN$4, O$11 * 0.876) - (O$11 * $N17)) * 0.25, 0 )} -> 0 | P17: {=IF( AND($H17 > $BN$7, Tabella01MarzoInverter[[#This Row],[Active power TX1-INV-2]] <= 0), IF( Tabella01MarzoInverter[[#This Row],[TX1 - Average Power]:[TX1 - Average Power]] > 0, Tabella01MarzoInverter[[#This Row],[TX1 - Average Power]:[TX1 - Average Power]] * 0.25, ($H17 / 1000) * P$10 * $BN$4 * 0.25 ), 0 ) + IF( $N17 < 0.875, MAX(0, MIN(($H17 / 1000) * P$10 * $BN$4, P$11 * 0.876) - (P$11 * $N17)) * 0.25, 0 )} -> 0 | Q17: {=IF( AND($H17 > $BN$7, Tabella01MarzoInverter[[#This Row],[Active power TX1-INV-3]] <= 0), IF( Tabella01MarzoInverter[[#This Row],[TX1 - Average Power]:[TX1 - Average Power]] > 0, Tabella01MarzoInverter[[#This Row],[TX1 - Average Power]:[TX1 - Average Power]] * 0.25, ($H17 / 1000) * Q$10 * $BN$4 * 0.25 ), 0 ) + IF( $N17 < 0.875, MAX(0, MIN(($H17 / 1000) * Q$10 * $BN$4, Q$11 * 0.876) - (Q$11 * $N17)) * 0.25, 0 )} -> 0 | R17: {=IF( AND($H17 > $BN$7, Tabella01MarzoInverter[[#This Row],[Active power TX1-INV-4]] <= 0), IF( Tabella01MarzoInverter[[#This Row],[TX1 - Average Power]:[TX1 - Average Power]] > 0, Tabella01MarzoInverter[[#This Row],[TX1 - Average Power]:[TX1 - Average Power]] * 0.25, ($H17 / 1000) * R$10 * $BN$4 * 0.25 ), 0 ) + IF( $N17 < 0.875, MAX(0, MIN(($H17 / 1000) * R$10 * $BN$4, R$11 * 0.876) - (R$11 * $N17)) * 0.25, 0 )} -> 0 | S17: {=IF( AND($H17 > $BN$7, Tabella01MarzoInverter[[#This Row],[Active power TX1-INV-5]] <= 0), IF( Tabella01MarzoInverter[[#This Row],[TX1 - Average Power]:[TX1 - Average Power]] > 0, Tabella01MarzoInverter[[#This Row],[TX1 - Average Power]:[TX1 - Average Power]] * 0.25, ($H17 / 1000) * S$10 * $BN$4 * 0.25 ), 0 ) + IF( $N17 < 0.875, MAX(0, MIN(($H17 / 1000) * S$10 * $BN$4, S$11 * 0.876) - (S$11 * $N17)) * 0.25, 0 )} -> 0 | T17: {=IF( AND($H17 > $BN$7, Tabella01MarzoInverter[[#This Row],[Active power TX1-INV-6]] <= 0), IF( Tabella01MarzoInverter[[#This Row],[TX1 - Average Power]:[TX1 - Average Power]] > 0, Tabella01MarzoInverter[[#This Row],[TX1 - Average Power]:[TX1 - Average Power]] * 0.25, ($H17 / 1000) * T$10 * $BN$4 * 0.25 ), 0 ) + IF( $N17 < 0.875, MAX(0, MIN(($H17 / 1000) * T$10 * $BN$4, T$11 * 0.876) - (T$11 * $N17)) * 0.25, 0 )} -> 0 | U17: {=IF( AND($H17 > $BN$7, Tabella01MarzoInverter[[#This Row],[Active power TX1-INV-7]] <= 0), IF( Tabella01MarzoInverter[[#This Row],[TX1 - Average Power]:[TX1 - Average Power]] > 0, Tabella01MarzoInverter[[#This Row],[TX1 - Average Power]:[TX1 - Average Power]] * 0.25, ($H17 / 1000) * U$10 * $BN$4 * 0.25 ), 0 ) + IF( $N17 < 0.875, MAX(0, MIN(($H17 / 1000) * U$10 * $BN$4, U$11 * 0.876) - (U$11 * $N17)) * 0.25, 0 )} -> 0 | V17: {=IF( AND($H17 > $BN$7, Tabella01MarzoInverter[[#This Row],[Active power TX1-INV-8]] <= 0), IF( Tabella01MarzoInverter[[#This Row],[TX1 - Average Power]:[TX1 - Average Power]] > 0, Tabella01MarzoInverter[[#This Row],[TX1 - Average Power]:[TX1 - Average Power]] * 0.25, ($H17 / 1000) * V$10 * $BN$4 * 0.25 ), 0 ) + IF( $N17 < 0.875, MAX(0, MIN(($H17 / 1000) * V$10 * $BN$4, V$11 * 0.876) - (V$11 * $N17)) * 0.25, 0 )} -> 0 | W17: {=IF( AND($H17 > $BN$7, Tabella01MarzoInverter[[#This Row],[Active power TX1-INV-9]] <= 0), IF( Tabella01MarzoInverter[[#This Row],[TX1 - Average Power]:[TX1 - Average Power]] > 0, Tabella01MarzoInverter[[#This Row],[TX1 - Average Power]:[TX1 - Average Power]] * 0.25, ($H17 / 1000) * W$10 * $BN$4 * 0.25 ), 0 ) + IF( $N17 < 0.875, MAX(0, MIN(($H17 / 1000) * W$10 * $BN$4, W$11 * 0.876) - (W$11 * $N17)) * 0.25, 0 )} -> 0 | X17: {=IF( AND($H17 > $BN$7, Tabella01MarzoInverter[[#This Row],[Active power TX1-INV-10]] <= 0), IF( Tabella01MarzoInverter[[#This Row],[TX1 - Average Power]:[TX1 - Average Power]] > 0, Tabella01MarzoInverter[[#This Row],[TX1 - Average Power]:[TX1 - Average Power]] * 0.25, ($H17 / 1000) * X$10 * $BN$4 * 0.25 ), 0 ) + IF( $N17 < 0.875, MAX(0, MIN(($H17 / 1000) * X$10 * $BN$4, X$11 * 0.876) - (X$11 * $N17)) * 0.25, 0 )} -> 0 | Y17: {=IF( AND($H17 > $BN$7, Tabella01MarzoInverter[[#This Row],[Active power TX1-INV-11]] <= 0), IF( Tabella01MarzoInverter[[#This Row],[TX1 - Average Power]:[TX1 - Average Power]] > 0, Tabella01MarzoInverter[[#This Row],[TX1 - Average Power]:[TX1 - Average Power]] * 0.25, ($H17 / 1000) * Y$10 * $BN$4 * 0.25 ), 0 ) + IF( $N17 < 0.875, MAX(0, MIN(($H17 / 1000) * Y$10 * $BN$4, Y$11 * 0.876) - (Y$11 * $N17)) * 0.25, 0 )} -> 0 | Z17: {=IF( AND($H17 > $BN$7, Tabella01MarzoInverter[[#This Row],[Active power TX1-INV-12]] <= 0), IF( Tabella01MarzoInverter[[#This Row],[TX1 - Average Power]:[TX1 - Average Power]] > 0, Tabella01MarzoInverter[[#This Row],[TX1 - Average Power]:[TX1 - Average Power]] * 0.25, ($H17 / 1000) * Z$10 * $BN$4 * 0.25 ), 0 ) + IF( $N17 < 0.875, MAX(0, MIN(($H17 / 1000) * Z$10 * $BN$4, Z$11 * 0.876) - (Z$11 * $N17)) * 0.25, 0 )} -> 0 | AA17: =AVERAGE(TabellaMar2026[[#This Row],[Colonna24]:[Colonna20]]) -> 0 | AB17: =MAX(TabellaMar2026[[#This Row],[Colonna24]:[Colonna20]]) -> 0 | AC17: =MIN(TabellaMar2026[[#This Row],[Colonna24]:[Colonna20]]) -> 0 | AD17: =SUM(TabellaMar2026[[#This Row],[Colonna24]:[Colonna20]]) -> 0 | AE17: =IF( AND($H17 > $BN$7, Tabella01MarzoInverter[[#This Row],[Active power TX2-INV-1]] <= 0, Tabella01MarzoInverter[[#This Row],[TX2 - Average Power]] <= 0), MIN(($H17 / 1000) * AE$10 * $BN$4, AE$11 * 0.876) * 0.25, IF( AND($H17 > $BN$7, Tabella01MarzoInverter[[#This Row],[Active power TX2-INV-1]] <= 0), Tabella01MarzoInverter[[#This Row],[TX2 - Average Power]] * 0.25, 0 ) + IF( $N17 < 0.875, MAX(0, MIN(($H17 / 1000) * AE$10 * $BN$4, AE$11 * 0.876) - (AE$11 * $N17)) * 0.25, 0 ) ) -> 0 | AF17: =IF( AND($H17 > $BN$7, Tabella01MarzoInverter[[#This Row],[Active power TX2-INV-2]] <= 0, Tabella01MarzoInverter[[#This Row],[TX2 - Max Power]] <= 0), MIN(($H17 / 1000) * AF$10 * $BN$4, AF$11 * 0.876) * 0.25, IF( AND($H17 > $BN$7, Tabella01MarzoInverter[[#This Row],[Active power TX2-INV-2]] <= 0), Tabella01MarzoInverter[[#This Row],[TX2 - Max Power]] * 0.25, 0 ) + IF( $N17 < 0.875, MAX(0, MIN(($H17 / 1000) * AF$10 * $BN$4, AF$11 * 0.876) - (AF$11 * $N17)) * 0.25, 0 ) ) -> 0 | AG17: =IF( AND($H17 > $BN$7, Tabella01MarzoInverter[[#This Row],[Active power TX2-INV-3]] <= 0, Tabella01MarzoInverter[[#This Row],[TX2 - Min Power]] <= 0), MIN(($H17 / 1000) * AG$10 * $BN$4, AG$11 * 0.876) * 0.25, IF( AND($H17 > $BN$7, Tabella01MarzoInverter[[#This Row],[Active power TX2-INV-3]] <= 0), Tabella01MarzoInverter[[#This Row],[TX2 - Min Power]] * 0.25, 0 ) + IF( $N17 < 0.875, MAX(0, MIN(($H17 / 1000) * AG$10 * $BN$4, AG$11 * 0.876) - (AG$11 * $N17)) * 0.25, 0 ) ) -> 0 | AH17: =IF( AND($H17 > $BN$7, Tabella01MarzoInverter[[#This Row],[Active power TX2-INV-4]] <= 0, Tabella01MarzoInverter[[#This Row],[Active power TX3-INV-1]] <= 0), MIN(($H17 / 1000) * AH$10 * $BN$4, AH$11 * 0.876) * 0.25, IF( AND($H17 > $BN$7, Tabella01MarzoInverter[[#This Row],[Active power TX2-INV-4]] <= 0), Tabella01MarzoInverter[[#This Row],[Active power TX3-INV-1]] * 0.25, 0 ) + IF( $N17 < 0.875, MAX(0, MIN(($H17 / 1000) * AH$10 * $BN$4, AH$11 * 0.876) - (AH$11 * $N17)) * 0.25, 0 ) ) -> 0 | AI17: =IF( AND($H17 > $BN$7, Tabella01MarzoInverter[[#This Row],[Active power TX2-INV-5]] <= 0, Tabella01MarzoInverter[[#This Row],[Active power TX3-INV-2]] <= 0), MIN(($H17 / 1000) * AI$10 * $BN$4, AI$11 * 0.876) * 0.25, IF( AND($H17 > $BN$7, Tabella01MarzoInverter[[#This Row],[Active power TX2-INV-5]] <= 0), Tabella01MarzoInverter[[#This Row],[Active power TX3-INV-2]] * 0.25, 0 ) + IF( $N17 < 0.875, MAX(0, MIN(($H17 / 1000) * AI$10 * $BN$4, AI$11 * 0.876) - (AI$11 * $N17)) * 0.25, 0 ) ) -> 0 | AJ17: =IF( AND($H17 > $BN$7, Tabella01MarzoInverter[[#This Row],[Active power TX2-INV-6]] <= 0, Tabella01MarzoInverter[[#This Row],[Active power TX3-INV-3]] <= 0), MIN(($H17 / 1000) * AJ$10 * $BN$4, AJ$11 * 0.876) * 0.25, IF( AND($H17 > $BN$7, Tabella01MarzoInverter[[#This Row],[Active power TX2-INV-6]] <= 0), Tabella01MarzoInverter[[#This Row],[Active power TX3-INV-3]] * 0.25, 0 ) + IF( $N17 < 0.875, MAX(0, MIN(($H17 / 1000) * AJ$10 * $BN$4, AJ$11 * 0.876) - (AJ$11 * $N17)) * 0.25, 0 ) ) -> 0 | AK17: =IF( AND($H17 > $BN$7, Tabella01MarzoInverter[[#This Row],[Active power TX2-INV-7]] <= 0, Tabella01MarzoInverter[[#This Row],[Active power TX3-INV-4]] <= 0), MIN(($H17 / 1000) * AK$10 * $BN$4, AK$11 * 0.876) * 0.25, IF( AND($H17 > $BN$7, Tabella01MarzoInverter[[#This Row],[Active power TX2-INV-7]] <= 0), Tabella01MarzoInverter[[#This Row],[Active power TX3-INV-4]] * 0.25, 0 ) + IF( $N17 < 0.875, MAX(0, MIN(($H17 / 1000) * AK$10 * $BN$4, AK$11 * 0.876) - (AK$11 * $N17)) * 0.25, 0 ) ) -> 0 | AL17: =IF( AND($H17 > $BN$7, Tabella01MarzoInverter[[#This Row],[Active power TX2-INV-8]] <= 0, Tabella01MarzoInverter[[#This Row],[Active power TX3-INV-5]] <= 0), MIN(($H17 / 1000) * AL$10 * $BN$4, AL$11 * 0.876) * 0.25, IF( AND($H17 > $BN$7, Tabella01MarzoInverter[[#This Row],[Active power TX2-INV-8]] <= 0), Tabella01MarzoInverter[[#This Row],[Active power TX3-INV-5]] * 0.25, 0 ) + IF( $N17 < 0.875, MAX(0, MIN(($H17 / 1000) * AL$10 * $BN$4, AL$11 * 0.876) - (AL$11 * $N17)) * 0.25, 0 ) ) -> 0 | AM17: =IF( AND($H17 > $BN$7, Tabella01MarzoInverter[[#This Row],[Active power TX2-INV-9]] <= 0, Tabella01MarzoInverter[[#This Row],[Active power TX3-INV-6]] <= 0), MIN(($H17 / 1000) * AM$10 * $BN$4, AM$11 * 0.876) * 0.25, IF( AND($H17 > $BN$7, Tabella01MarzoInverter[[#This Row],[Active power TX2-INV-9]] <= 0), Tabella01MarzoInverter[[#This Row],[Active power TX3-INV-6]] * 0.25, 0 ) + IF( $N17 < 0.875, MAX(0, MIN(($H17 / 1000) * AM$10 * $BN$4, AM$11 * 0.876) - (AM$11 * $N17)) * 0.25, 0 ) ) -> 0 | AN17: =IF( AND($H17 > $BN$7, Tabella01MarzoInverter[[#This Row],[Active power TX2-INV-10]] <= 0, Tabella01MarzoInverter[[#This Row],[Active power TX3-INV-7]] <= 0), MIN(($H17 / 1000) * AN$10 * $BN$4, AN$11 * 0.876) * 0.25, IF( AND($H17 > $BN$7, Tabella01MarzoInverter[[#This Row],[Active power TX2-INV-10]] <= 0), Tabella01MarzoInverter[[#This Row],[Active power TX3-INV-7]] * 0.25, 0 ) + IF( $N17 < 0.875, MAX(0, MIN(($H17 / 1000) * AN$10 * $BN$4, AN$11 * 0.876) - (AN$11 * $N17)) * 0.25, 0 ) ) -> 0 | AO17: =IF( AND($H17 > $BN$7, Tabella01MarzoInverter[[#This Row],[Active power TX2-INV-11]] <= 0, Tabella01MarzoInverter[[#This Row],[Active power TX3-INV-8]] <= 0), MIN(($H17 / 1000) * AO$10 * $BN$4, AO$11 * 0.876) * 0.25, IF( AND($H17 > $BN$7, Tabella01MarzoInverter[[#This Row],[Active power TX2-INV-11]] <= 0), Tabella01MarzoInverter[[#This Row],[Active power TX3-INV-8]] * 0.25, 0 ) + IF( $N17 < 0.875, MAX(0, MIN(($H17 / 1000) * AO$10 * $BN$4, AO$11 * 0.876) - (AO$11 * $N17)) * 0.25, 0 ) ) -> 0 | AP17: =IF( AND($H17 > $BN$7, Tabella01MarzoInverter[[#This Row],[Active power TX2-INV-12]] <= 0, Tabella01MarzoInverter[[#This Row],[Active power TX3-INV-9]] <= 0), MIN(($H17 / 1000) * AP$10 * $BN$4, AP$11 * 0.876) * 0.25, IF( AND($H17 > $BN$7, Tabella01MarzoInverter[[#This Row],[Active power TX2-INV-12]] <= 0), Tabella01MarzoInverter[[#This Row],[Active power TX3-INV-9]] * 0.25, 0 ) + IF( $N17 < 0.875, MAX(0, MIN(($H17 / 1000) * AP$10 * $BN$4, AP$11 * 0.876) - (AP$11 * $N17)) * 0.25, 0 ) ) -> 0 | AQ17: =AVERAGE(TabellaMar2026[[#This Row],[Colonna39]:[Colonna6]]) -> 0 | AR17: =MAX(TabellaMar2026[[#This Row],[Colonna39]:[Colonna6]]) -> 0 | AS17: =MIN(TabellaMar2026[[#This Row],[Colonna39]:[Colonna6]]) -> 0 | AT17: =SUM(TabellaMar2026[[#This Row],[Colonna39]:[Colonna6]]) -> 0 | AU17: {=IF( AND($H17 > $BN$7, Tabella01MarzoInverter[[#This Row],[Active power TX3-INV-1]] <= 0), IF( Tabella01MarzoInverter[[#This Row],[TX3 - Average Power]:[TX3 - Average Power]] > 0, Tabella01MarzoInverter[[#This Row],[TX3 - Average Power]:[TX3 - Average Power]] * 0.25, ($H17 / 1000) * AU$10 * $BN$4 * 0.25 ), 0 ) + IF( $N17 < 0.875, MAX(0, MIN(($H17 / 1000) * AU$10 * $BN$4, AU$11 * 0.876) - (AU$11 * $N17)) * 0.25, 0 )} -> 0 | AV17: {=IF( AND($H17 > $BN$7, Tabella01MarzoInverter[[#This Row],[Active power TX3-INV-2]] <= 0), IF( Tabella01MarzoInverter[[#This Row],[TX3 - Average Power]:[TX3 - Average Power]] > 0, Tabella01MarzoInverter[[#This Row],[TX3 - Average Power]:[TX3 - Average Power]] * 0.25, ($H17 / 1000) * AV$10 * $BN$4 * 0.25 ), 0 ) + IF( $N17 < 0.875, MAX(0, MIN(($H17 / 1000) * AV$10 * $BN$4, AV$11 * 0.876) - (AV$11 * $N17)) * 0.25, 0 )} -> 0 | AW17: {=IF( AND($H17 > $BN$7, Tabella01MarzoInverter[[#This Row],[Active power TX3-INV-3]] <= 0), IF( Tabella01MarzoInverter[[#This Row],[TX3 - Average Power]:[TX3 - Average Power]] > 0, Tabella01MarzoInverter[[#This Row],[TX3 - Average Power]:[TX3 - Average Power]] * 0.25, ($H17 / 1000) * AW$10 * $BN$4 * 0.25 ), 0 ) + IF( $N17 < 0.875, MAX(0, MIN(($H17 / 1000) * AW$10 * $BN$4, AW$11 * 0.876) - (AW$11 * $N17)) * 0.25, 0 )} -> 0 | AX17: {=IF( AND($H17 > $BN$7, Tabella01MarzoInverter[[#This Row],[Active power TX3-INV-4]] <= 0), IF( Tabella01MarzoInverter[[#This Row],[TX3 - Average Power]:[TX3 - Average Power]] > 0, Tabella01MarzoInverter[[#This Row],[TX3 - Average Power]:[TX3 - Average Power]] * 0.25, ($H17 / 1000) * AX$10 * $BN$4 * 0.25 ), 0 ) + IF( $N17 < 0.875, MAX(0, MIN(($H17 / 1000) * AX$10 * $BN$4, AX$11 * 0.876) - (AX$11 * $N17)) * 0.25, 0 )} -> 0 | AY17: {=IF( AND($H17 > $BN$7, Tabella01MarzoInverter[[#This Row],[Active power TX3-INV-5]] <= 0), IF( Tabella01MarzoInverter[[#This Row],[TX3 - Average Power]:[TX3 - Average Power]] > 0, Tabella01MarzoInverter[[#This Row],[TX3 - Average Power]:[TX3 - Average Power]] * 0.25, ($H17 / 1000) * AY$10 * $BN$4 * 0.25 ), 0 ) + IF( $N17 < 0.875, MAX(0, MIN(($H17 / 1000) * AY$10 * $BN$4, AY$11 * 0.876) - (AY$11 * $N17)) * 0.25, 0 )} -> 0 | AZ17: {=IF( AND($H17 > $BN$7, Tabella01MarzoInverter[[#This Row],[Active power TX3-INV-6]] <= 0), IF( Tabella01MarzoInverter[[#This Row],[TX3 - Average Power]:[TX3 - Average Power]] > 0, Tabella01MarzoInverter[[#This Row],[TX3 - Average Power]:[TX3 - Average Power]] * 0.25, ($H17 / 1000) * AZ$10 * $BN$4 * 0.25 ), 0 ) + IF( $N17 < 0.875, MAX(0, MIN(($H17 / 1000) * AZ$10 * $BN$4, AZ$11 * 0.876) - (AZ$11 * $N17)) * 0.25, 0 )} -> 0 | BA17: {=IF( AND($H17 > $BN$7, Tabella01MarzoInverter[[#This Row],[Active power TX3-INV-7]] <= 0), IF( Tabella01MarzoInverter[[#This Row],[TX3 - Average Power]:[TX3 - Average Power]] > 0, Tabella01MarzoInverter[[#This Row],[TX3 - Average Power]:[TX3 - Average Power]] * 0.25, ($H17 / 1000) * BA$10 * $BN$4 * 0.25 ), 0 ) + IF( $N17 < 0.875, MAX(0, MIN(($H17 / 1000) * BA$10 * $BN$4, BA$11 * 0.876) - (BA$11 * $N17)) * 0.25, 0 )} -> 0 | BB17: {=IF( AND($H17 > $BN$7, Tabella01MarzoInverter[[#This Row],[Active power TX3-INV-8]] <= 0), IF( Tabella01MarzoInverter[[#This Row],[TX3 - Average Power]:[TX3 - Average Power]] > 0, Tabella01MarzoInverter[[#This Row],[TX3 - Average Power]:[TX3 - Average Power]] * 0.25, ($H17 / 1000) * BB$10 * $BN$4 * 0.25 ), 0 ) + IF( $N17 < 0.875, MAX(0, MIN(($H17 / 1000) * BB$10 * $BN$4, BB$11 * 0.876) - (BB$11 * $N17)) * 0.25, 0 )} -> 0 | BC17: {=IF( AND($H17 > $BN$7, Tabella01MarzoInverter[[#This Row],[Active power TX3-INV-9]] <= 0), IF( Tabella01MarzoInverter[[#This Row],[TX3 - Average Power]:[TX3 - Average Power]] > 0, Tabella01MarzoInverter[[#This Row],[TX3 - Average Power]:[TX3 - Average Power]] * 0.25, ($H17 / 1000) * BC$10 * $BN$4 * 0.25 ), 0 ) + IF( $N17 < 0.875, MAX(0, MIN(($H17 / 1000) * BC$10 * $BN$4, BC$11 * 0.876) - (BC$11 * $N17)) * 0.25, 0 )} -> 0 | BD17: {=IF( AND($H17 > $BN$7, Tabella01MarzoInverter[[#This Row],[Active power TX3-INV-10]] <= 0), IF( Tabella01MarzoInverter[[#This Row],[TX3 - Average Power]:[TX3 - Average Power]] > 0, Tabella01MarzoInverter[[#This Row],[TX3 - Average Power]:[TX3 - Average Power]] * 0.25, ($H17 / 1000) * BD$10 * $BN$4 * 0.25 ), 0 ) + IF( $N17 < 0.875, MAX(0, MIN(($H17 / 1000) * BD$10 * $BN$4, BD$11 * 0.876) - (BD$11 * $N17)) * 0.25, 0 )} -> 0 | BE17: {=IF( AND($H17 > $BN$7, Tabella01MarzoInverter[[#This Row],[Active power TX3-INV-11]] <= 0), IF( Tabella01MarzoInverter[[#This Row],[TX3 - Average Power]:[TX3 - Average Power]] > 0, Tabella01MarzoInverter[[#This Row],[TX3 - Average Power]:[TX3 - Average Power]] * 0.25, ($H17 / 1000) * BE$10 * $BN$4 * 0.25 ), 0 ) + IF( $N17 < 0.875, MAX(0, MIN(($H17 / 1000) * BE$10 * $BN$4, BE$11 * 0.876) - (BE$11 * $N17)) * 0.25, 0 )} -> 0 | BF17: {=IF( AND($H17 > $BN$7, Tabella01MarzoInverter[[#This Row],[Active power TX3-INV-12]] <= 0), IF( Tabella01MarzoInverter[[#This Row],[TX3 - Average Power]:[TX3 - Average Power]] > 0, Tabella01MarzoInverter[[#This Row],[TX3 - Average Power]:[TX3 - Average Power]] * 0.25, ($H17 / 1000) * BF$10 * $BN$4 * 0.25 ), 0 ) + IF( $N17 < 0.875, MAX(0, MIN(($H17 / 1000) * BF$10 * $BN$4, BF$11 * 0.876) - (BF$11 * $N17)) * 0.25, 0 )} -> 0 | BG17: =AVERAGE(TabellaMar2026[[#This Row],[Colonna55]:[Colonna53]]) -> 0 | BH17: =MAX(TabellaMar2026[[#This Row],[Colonna55]:[Colonna53]]) -> 0 | BI17: =MIN(TabellaMar2026[[#This Row],[Colonna55]:[Colonna53]]) -> 0 | BJ17: =SUM(TabellaMar2026[[#This Row],[Colonna54]:[Colonna53]]) -> 0 | BK17: =(SUM(Tabella01MarzoInverter[[Active power TX1-INV-1]:[Active power TX3-INV-12]]) * 0.25) / (12625 * (SUM($G$15:$H$110) * 0.25 / 1000)) -> 1.0142296
